Workbook

Sheet Runs Overview
A1: Challenge Task
A2: Run ID | C2: 1 | D2: 2 | E2: 3 | F2: 4 | G2: 5 | H2: 6 | I2: 7 | J2: 8 | K2: 9 | L2: 10 | M2: 11 | N2: 12 | O2: 13 | P2: 14 | Q2: 15 | R2: 16 | S2: 17 | T2: 18 | U2: 19 | V2: 20 | W2: 21 | X2: 22 | Y2: 23 | Z2: 24 | AA2: 25 | AB2: 26 | AC2: 27 | AD2: 28 | AE2: 29 | AF2: 30 | AG2: 31 | AH2: 32 | AI2: 33
A3: Group Name | C3: AIINS-11 | D3: CERTH-ITI | E3: CERTH-ITI | F3: CERTH-ITI | G3: CERTH-ITI | H3: CERTH-ITI | I3: CERTH-ITI | J3: CERTH-ITI | K3: CERTH-ITI | L3: CERTH-ITI | M3: CERTH-ITI | N3: FAST-DS | O3: FAST-DS | P3: FAST-DS | Q3: FAST-DS | R3: FAST-DS | S3: FAST-DS | T3: FAST-MS | U3: FAST-MS | V3: FAST-MS | W3: NewsWeavers | X3: NewsWeavers | Y3: NewsWeavers | Z3: NewsWeavers | AA3: TEAM-A++ | AB3: UAmsterdam | AC3: UAmsterdam | AD3: UAmsterdam | AE3: BASELINE | AF3: FAST-MS | AG3: Insight | AH3: Insight | AI3: Insight
A4: Run Name | C4: PD12MTFIDF | D4: Run 10 | E4: Run 1 | F4: Run 2 | G4: Run 3 | H4: Run 4 | I4: Run 5 | J4: Run 6 | K4: Run 7 | L4: Run 8 | M4: Run 9 | N4: QueryForge-RX | O4: QueryForge-VGQE | P4: QueryForge-VGRX | Q4: QueryForge | R4: VisionAnchor-R | S4: VisionAnchor | T4: Basic Retrieval | U4: Hybrid Retrieval | V4: Official Retrieval | W4: Qwen 3B Plan LoRA FLUX | X4: Qwen 3B Plan LoRA SDXL | Y4: Qwen 3B Plan Prompt Zero Shot FLUX | Z4: Qwen 3B Plan Prompt Zero Shot SDXL | AA4: SDXL-CFT | AB4: Flux Black-White Caricature | AC4: Qwen Color Caricature | AD4: Z-Image Caricature | AE4: Original Images | AF4: RealVISXL | AG4: FireRed-Image-Edit-1.1 | AH4: Flux.2 Klein | AI4: Qwen-Image-Edit-2519
A5: Run AVG (GROUPED TEAMS) | C5: =AVERAGE('Survey Results'!E39,'Survey Results'!AM39,'Survey Results'!BU39,'Survey Results'!DC39,'Survey Results'!EK39,'Survey Results'!FS39,'Survey Results'!HA39,'Survey Results'!IF39,'Survey Results'!JK39,'Survey Results'!KP39,'Survey Results'!LU39,'Survey Results'!MZ39,'Survey Results'!OE39,'Survey Results'!PJ39,'Survey Results'!QO39,'Survey Results'!RT39,'Survey Results'!SY39,'Survey Results'!UD39,'Survey Results'!VI39,'Survey Results'!WN39,'Survey Results'!XS39,'Survey Results'!YX39,'Survey Results'!AAC39,'Survey Results'!ABH39,'Survey Results'!ACM39,'Survey Results'!ADR39,'Survey Results'!AEW39,'Survey Results'!AGB39,'Survey Results'!AHG39,'Survey Results'!AIL39,'Survey Results'!AJQ39,'Survey Results'!AKV39,'Survey Results'!AMA39,'Survey Results'!ANF39,'Survey Results'!AOK39) -> 1.6902041 | D5: =AVERAGE('Survey Results'!F39,'Survey Results'!AN39,'Survey Results'!BV39,'Survey Results'!DD39,'Survey Results'!EL39,'Survey Results'!FT39,'Survey Results'!HB39,'Survey Results'!IG39,'Survey Results'!JL39,'Survey Results'!KQ39,'Survey Results'!LV39,'Survey Results'!NA39,'Survey Results'!OF39,'Survey Results'!PK39,'Survey Results'!QP39,'Survey Results'!RU39,'Survey Results'!SZ39,'Survey Results'!UE39,'Survey Results'!VJ39,'Survey Results'!WO39,'Survey Results'!XT39,'Survey Results'!YY39,'Survey Results'!AAD39,'Survey Results'!ABI39,'Survey Results'!ACN39,'Survey Results'!ADS39,'Survey Results'!AEX39,'Survey Results'!AGC39,'Survey Results'!AHH39,'Survey Results'!AIM39,'Survey Results'!AJR39,'Survey Results'!AKW39,'Survey Results'!AMB39,'Survey Results'!ANG39,'Survey Results'!AOL39) -> 3.5089796 | E5: =AVERAGE('Survey Results'!G39,'Survey Results'!AO39,'Survey Results'!BW39,'Survey Results'!DE39,'Survey Results'!EM39,'Survey Results'!FU39,'Survey Results'!HC39,'Survey Results'!IH39,'Survey Results'!JM39,'Survey Results'!KR39,'Survey Results'!LW39,'Survey Results'!NB39,'Survey Results'!OG39,'Survey Results'!PL39,'Survey Results'!QQ39,'Survey Results'!RV39,'Survey Results'!TA39,'Survey Results'!UF39,'Survey Results'!VK39,'Survey Results'!WP39,'Survey Results'!XU39,'Survey Results'!YZ39,'Survey Results'!AAE39,'Survey Results'!ABJ39,'Survey Results'!ACO39,'Survey Results'!ADT39,'Survey Results'!AEY39,'Survey Results'!AGD39,'Survey Results'!AHI39,'Survey Results'!AIN39,'Survey Results'!AJS39,'Survey Results'!AKX39,'Survey Results'!AMC39,'Survey Results'!ANH39,'Survey Results'!AOM39) -> 3.5542857 | F5: =AVERAGE('Survey Results'!H39,'Survey Results'!AP39,'Survey Results'!BX39,'Survey Results'!DF39,'Survey Results'!EN39,'Survey Results'!FV39,'Survey Results'!HD39,'Survey Results'!II39,'Survey Results'!JN39,'Survey Results'!KS39,'Survey Results'!LX39,'Survey Results'!NC39,'Survey Results'!OH39,'Survey Results'!PM39,'Survey Results'!QR39,'Survey Results'!RW39,'Survey Results'!TB39,'Survey Results'!UG39,'Survey Results'!VL39,'Survey Results'!WQ39,'Survey Results'!XV39,'Survey Results'!ZA39,'Survey Results'!AAF39,'Survey Results'!ABK39,'Survey Results'!ACP39,'Survey Results'!ADU39,'Survey Results'!AEZ39,'Survey Results'!AGE39,'Survey Results'!AHJ39,'Survey Results'!AIO39,'Survey Results'!AJT39,'Survey Results'!AKY39,'Survey Results'!AMD39,'Survey Results'!ANI39,'Survey Results'!AON39) -> 3.615102 | G5: =AVERAGE('Survey Results'!I39,'Survey Results'!AQ39,'Survey Results'!BY39,'Survey Results'!DG39,'Survey Results'!EO39,'Survey Results'!FW39,'Survey Results'!HE39,'Survey Results'!IJ39,'Survey Results'!JO39,'Survey Results'!KT39,'Survey Results'!LY39,'Survey Results'!ND39,'Survey Results'!OI39,'Survey Results'!PN39,'Survey Results'!QS39,'Survey Results'!RX39,'Survey Results'!TC39,'Survey Results'!UH39,'Survey Results'!VM39,'Survey Results'!WR39,'Survey Results'!XW39,'Survey Results'!ZB39,'Survey Results'!AAG39,'Survey Results'!ABL39,'Survey Results'!ACQ39,'Survey Results'!ADV39,'Survey Results'!AFA39,'Survey Results'!AGF39,'Survey Results'!AHK39,'Survey Results'!AIP39,'Survey Results'!AJU39,'Survey Results'!AKZ39,'Survey Results'!AME39,'Survey Results'!ANJ39,'Survey Results'!AOO39) -> 3.4730612 | H5: =AVERAGE('Survey Results'!J39,'Survey Results'!AR39,'Survey Results'!BZ39,'Survey Results'!DH39,'Survey Results'!EP39,'Survey Results'!FX39,'Survey Results'!HF39,'Survey Results'!IK39,'Survey Results'!JP39,'Survey Results'!KU39,'Survey Results'!LZ39,'Survey Results'!NE39,'Survey Results'!OJ39,'Survey Results'!PO39,'Survey Results'!QT39,'Survey Results'!RY39,'Survey Results'!TD39,'Survey Results'!UI39,'Survey Results'!VN39,'Survey Results'!WS39,'Survey Results'!XX39,'Survey Results'!ZC39,'Survey Results'!AAH39,'Survey Results'!ABM39,'Survey Results'!ACR39,'Survey Results'!ADW39,'Survey Results'!AFB39,'Survey Results'!AGG39,'Survey Results'!AHL39,'Survey Results'!AIQ39,'Survey Results'!AJV39,'Survey Results'!ALA39,'Survey Results'!AMF39,'Survey Results'!ANK39,'Survey Results'!AOP39) -> 3.5702041 | I5: =AVERAGE('Survey Results'!K39,'Survey Results'!AS39,'Survey Results'!CA39,'Survey Results'!DI39,'Survey Results'!EQ39,'Survey Results'!FY39,'Survey Results'!HG39,'Survey Results'!IL39,'Survey Results'!JQ39,'Survey Results'!KV39,'Survey Results'!MA39,'Survey Results'!NF39,'Survey Results'!OK39,'Survey Results'!PP39,'Survey Results'!QU39,'Survey Results'!RZ39,'Survey Results'!TE39,'Survey Results'!UJ39,'Survey Results'!VO39,'Survey Results'!WT39,'Survey Results'!XY39,'Survey Results'!ZD39,'Survey Results'!AAI39,'Survey Results'!ABN39,'Survey Results'!ACS39,'Survey Results'!ADX39,'Survey Results'!AFC39,'Survey Results'!AGH39,'Survey Results'!AHM39,'Survey Results'!AIR39,'Survey Results'!AJW39,'Survey Results'!ALB39,'Survey Results'!AMG39,'Survey Results'!ANL39,'Survey Results'!AOQ39) -> 3.5073469 | J5: =AVERAGE('Survey Results'!L39,'Survey Results'!AT39,'Survey Results'!CB39,'Survey Results'!DJ39,'Survey Results'!ER39,'Survey Results'!FZ39,'Survey Results'!HH39,'Survey Results'!IM39,'Survey Results'!JR39,'Survey Results'!KW39,'Survey Results'!MB39,'Survey Results'!NG39,'Survey Results'!OL39,'Survey Results'!PQ39,'Survey Results'!QV39,'Survey Results'!SA39,'Survey Results'!TF39,'Survey Results'!UK39,'Survey Results'!VP39,'Survey Results'!WU39,'Survey Results'!XZ39,'Survey Results'!ZE39,'Survey Results'!AAJ39,'Survey Results'!ABO39,'Survey Results'!ACT39,'Survey Results'!ADY39,'Survey Results'!AFD39,'Survey Results'!AGI39,'Survey Results'!AHN39,'Survey Results'!AIS39,'Survey Results'!AJX39,'Survey Results'!ALC39,'Survey Results'!AMH39,'Survey Results'!ANM39,'Survey Results'!AOR39) -> 3.6926531 | ... AF5: =AVERAGE('Survey Results'!AH39,'Survey Results'!BP39,'Survey Results'!CX39,'Survey Results'!EF39,'Survey Results'!FN39,'Survey Results'!GV39,'Survey Results'!ID39,'Survey Results'!JI39,'Survey Results'!KN39,'Survey Results'!LS39,'Survey Results'!MX39,'Survey Results'!OC39,'Survey Results'!PH39,'Survey Results'!QM39,'Survey Results'!RR39,'Survey Results'!SW39,'Survey Results'!UB39,'Survey Results'!VG39,'Survey Results'!WL39,'Survey Results'!XQ39,'Survey Results'!YV39,'Survey Results'!AAA39,'Survey Results'!ABF39,'Survey Results'!ACK39,'Survey Results'!ADP39,'Survey Results'!AEU39,'Survey Results'!AFZ39,'Survey Results'!AHE39,'Survey Results'!AIJ39,'Survey Results'!AJO39,'Survey Results'!AKT39,'Survey Results'!ALY39,'Survey Results'!AND39,'Survey Results'!AOI39,'Survey Results'!APN39) -> 3.3289796 | AG5: =AVERAGE('Survey Results'!AI38,'Survey Results'!BQ38,'Survey Results'!CY38,'Survey Results'!EG38,'Survey Results'!FO38,'Survey Results'!GW38) -> 3.2583333 | AH5: =AVERAGE('Survey Results'!AJ38,'Survey Results'!BR38,'Survey Results'!CZ38,'Survey Results'!EH38,'Survey Results'!FP38,'Survey Results'!GX38) -> 3.2708333 | AI5: =AVERAGE('Survey Results'!AK38,'Survey Results'!BS38,'Survey Results'!DA38,'Survey Results'!EI38,'Survey Results'!FQ38,'Survey Results'!GY38) -> 3.2958333
A6: Run AVG (GROUPED TEAMS AND GROUPED PROLIFIC) | C6: =AVERAGE('Survey Results'!E73,'Survey Results'!AM73,'Survey Results'!BU73,'Survey Results'!DC73,'Survey Results'!EK73,'Survey Results'!FS73,'Survey Results'!HA73,'Survey Results'!IF73,'Survey Results'!JK73,'Survey Results'!KP73,'Survey Results'!LU73,'Survey Results'!MZ73,'Survey Results'!OE73,'Survey Results'!PJ73,'Survey Results'!QO73,'Survey Results'!RT73,'Survey Results'!SY73,'Survey Results'!UD73,'Survey Results'!VI73,'Survey Results'!WN73,'Survey Results'!XS73,'Survey Results'!YX73,'Survey Results'!AAC73,'Survey Results'!ABH73,'Survey Results'!ACM73,'Survey Results'!ADR73,'Survey Results'!AEW73,'Survey Results'!AGB73,'Survey Results'!AHG73,'Survey Results'!AIL73,'Survey Results'!AJQ73,'Survey Results'!AKV73,'Survey Results'!AMA73,'Survey Results'!ANF73,'Survey Results'!AOK73) -> 1.6696088 | D6: =AVERAGE('Survey Results'!F73,'Survey Results'!AN73,'Survey Results'!BV73,'Survey Results'!DD73,'Survey Results'!EL73,'Survey Results'!FT73,'Survey Results'!HB73,'Survey Results'!IG73,'Survey Results'!JL73,'Survey Results'!KQ73,'Survey Results'!LV73,'Survey Results'!NA73,'Survey Results'!OF73,'Survey Results'!PK73,'Survey Results'!QP73,'Survey Results'!RU73,'Survey Results'!SZ73,'Survey Results'!UE73,'Survey Results'!VJ73,'Survey Results'!WO73,'Survey Results'!XT73,'Survey Results'!YY73,'Survey Results'!AAD73,'Survey Results'!ABI73,'Survey Results'!ACN73,'Survey Results'!ADS73,'Survey Results'!AEX73,'Survey Results'!AGC73,'Survey Results'!AHH73,'Survey Results'!AIM73,'Survey Results'!AJR73,'Survey Results'!AKW73,'Survey Results'!AMB73,'Survey Results'!ANG73,'Survey Results'!AOL73) -> 3.4663946 | E6: =AVERAGE('Survey Results'!G73,'Survey Results'!AO73,'Survey Results'!BW73,'Survey Results'!DE73,'Survey Results'!EM73,'Survey Results'!FU73,'Survey Results'!HC73,'Survey Results'!IH73,'Survey Results'!JM73,'Survey Results'!KR73,'Survey Results'!LW73,'Survey Results'!NB73,'Survey Results'!OG73,'Survey Results'!PL73,'Survey Results'!QQ73,'Survey Results'!RV73,'Survey Results'!TA73,'Survey Results'!UF73,'Survey Results'!VK73,'Survey Results'!WP73,'Survey Results'!XU73,'Survey Results'!YZ73,'Survey Results'!AAE73,'Survey Results'!ABJ73,'Survey Results'!ACO73,'Survey Results'!ADT73,'Survey Results'!AEY73,'Survey Results'!AGD73,'Survey Results'!AHI73,'Survey Results'!AIN73,'Survey Results'!AJS73,'Survey Results'!AKX73,'Survey Results'!AMC73,'Survey Results'!ANH73,'Survey Results'!AOM73) -> 3.5209524 | F6: =AVERAGE('Survey Results'!H73,'Survey Results'!AP73,'Survey Results'!BX73,'Survey Results'!DF73,'Survey Results'!EN73,'Survey Results'!FV73,'Survey Results'!HD73,'Survey Results'!II73,'Survey Results'!JN73,'Survey Results'!KS73,'Survey Results'!LX73,'Survey Results'!NC73,'Survey Results'!OH73,'Survey Results'!PM73,'Survey Results'!QR73,'Survey Results'!RW73,'Survey Results'!TB73,'Survey Results'!UG73,'Survey Results'!VL73,'Survey Results'!WQ73,'Survey Results'!XV73,'Survey Results'!ZA73,'Survey Results'!AAF73,'Survey Results'!ABK73,'Survey Results'!ACP73,'Survey Results'!ADU73,'Survey Results'!AEZ73,'Survey Results'!AGE73,'Survey Results'!AHJ73,'Survey Results'!AIO73,'Survey Results'!AJT73,'Survey Results'!AKY73,'Survey Results'!AMD73,'Survey Results'!ANI73,'Survey Results'!AON73) -> 3.5883844 | G6: =AVERAGE('Survey Results'!I73,'Survey Results'!AQ73,'Survey Results'!BY73,'Survey Results'!DG73,'Survey Results'!EO73,'Survey Results'!FW73,'Survey Results'!HE73,'Survey Results'!IJ73,'Survey Results'!JO73,'Survey Results'!KT73,'Survey Results'!LY73,'Survey Results'!ND73,'Survey Results'!OI73,'Survey Results'!PN73,'Survey Results'!QS73,'Survey Results'!RX73,'Survey Results'!TC73,'Survey Results'!UH73,'Survey Results'!VM73,'Survey Results'!WR73,'Survey Results'!XW73,'Survey Results'!ZB73,'Survey Results'!AAG73,'Survey Results'!ABL73,'Survey Results'!ACQ73,'Survey Results'!ADV73,'Survey Results'!AFA73,'Survey Results'!AGF73,'Survey Results'!AHK73,'Survey Results'!AIP73,'Survey Results'!AJU73,'Survey Results'!AKZ73,'Survey Results'!AME73,'Survey Results'!ANJ73,'Survey Results'!AOO73) -> 3.4433673 | H6: =AVERAGE('Survey Results'!J73,'Survey Results'!AR73,'Survey Results'!BZ73,'Survey Results'!DH73,'Survey Results'!EP73,'Survey Results'!FX73,'Survey Results'!HF73,'Survey Results'!IK73,'Survey Results'!JP73,'Survey Results'!KU73,'Survey Results'!LZ73,'Survey Results'!NE73,'Survey Results'!OJ73,'Survey Results'!PO73,'Survey Results'!QT73,'Survey Results'!RY73,'Survey Results'!TD73,'Survey Results'!UI73,'Survey Results'!VN73,'Survey Results'!WS73,'Survey Results'!XX73,'Survey Results'!ZC73,'Survey Results'!AAH73,'Survey Results'!ABM73,'Survey Results'!ACR73,'Survey Results'!ADW73,'Survey Results'!AFB73,'Survey Results'!AGG73,'Survey Results'!AHL73,'Survey Results'!AIQ73,'Survey Results'!AJV73,'Survey Results'!ALA73,'Survey Results'!AMF73,'Survey Results'!ANK73,'Survey Results'!AOP73) -> 3.5338605 | I6: =AVERAGE('Survey Results'!K73,'Survey Results'!AS73,'Survey Results'!CA73,'Survey Results'!DI73,'Survey Results'!EQ73,'Survey Results'!FY73,'Survey Results'!HG73,'Survey Results'!IL73,'Survey Results'!JQ73,'Survey Results'!KV73,'Survey Results'!MA73,'Survey Results'!NF73,'Survey Results'!OK73,'Survey Results'!PP73,'Survey Results'!QU73,'Survey Results'!RZ73,'Survey Results'!TE73,'Survey Results'!UJ73,'Survey Results'!VO73,'Survey Results'!WT73,'Survey Results'!XY73,'Survey Results'!ZD73,'Survey Results'!AAI73,'Survey Results'!ABN73,'Survey Results'!ACS73,'Survey Results'!ADX73,'Survey Results'!AFC73,'Survey Results'!AGH73,'Survey Results'!AHM73,'Survey Results'!AIR73,'Survey Results'!AJW73,'Survey Results'!ALB73,'Survey Results'!AMG73,'Survey Results'!ANL73,'Survey Results'!AOQ73) -> 3.4730782 | J6: =AVERAGE('Survey Results'!L73,'Survey Results'!AT73,'Survey Results'!CB73,'Survey Results'!DJ73,'Survey Results'!ER73,'Survey Results'!FZ73,'Survey Results'!HH73,'Survey Results'!IM73,'Survey Results'!JR73,'Survey Results'!KW73,'Survey Results'!MB73,'Survey Results'!NG73,'Survey Results'!OL73,'Survey Results'!PQ73,'Survey Results'!QV73,'Survey Results'!SA73,'Survey Results'!TF73,'Survey Results'!UK73,'Survey Results'!VP73,'Survey Results'!WU73,'Survey Results'!XZ73,'Survey Results'!ZE73,'Survey Results'!AAJ73,'Survey Results'!ABO73,'Survey Results'!ACT73,'Survey Results'!ADY73,'Survey Results'!AFD73,'Survey Results'!AGI73,'Survey Results'!AHN73,'Survey Results'!AIS73,'Survey Results'!AJX73,'Survey Results'!ALC73,'Survey Results'!AMH73,'Survey Results'!ANM73,'Survey Results'!AOR73) -> 3.672398 | ... AF6: =AVERAGE('Survey Results'!AH73,'Survey Results'!BP73,'Survey Results'!CX73,'Survey Results'!EF73,'Survey Results'!FN73,'Survey Results'!GV73,'Survey Results'!ID73,'Survey Results'!JI73,'Survey Results'!KN73,'Survey Results'!LS73,'Survey Results'!MX73,'Survey Results'!OC73,'Survey Results'!PH73,'Survey Results'!QM73,'Survey Results'!RR73,'Survey Results'!SW73,'Survey Results'!UB73,'Survey Results'!VG73,'Survey Results'!WL73,'Survey Results'!XQ73,'Survey Results'!YV73,'Survey Results'!AAA73,'Survey Results'!ABF73,'Survey Results'!ACK73,'Survey Results'!ADP73,'Survey Results'!AEU73,'Survey Results'!AFZ73,'Survey Results'!AHE73,'Survey Results'!AIJ73,'Survey Results'!AJO73,'Survey Results'!AKT73,'Survey Results'!ALY73,'Survey Results'!AND73,'Survey Results'!AOI73,'Survey Results'!APN73) -> 3.2951701 | AG6: =AVERAGE('Survey Results'!AI73,'Survey Results'!BQ73,'Survey Results'!CY73,'Survey Results'!EG73,'Survey Results'!FO73,'Survey Results'!GW73) -> 3.2020282 | AH6: =AVERAGE('Survey Results'!AJ73,'Survey Results'!BR73,'Survey Results'!CZ73,'Survey Results'!EH73,'Survey Results'!FP73,'Survey Results'!GX73) -> 3.1984127 | AI6: =AVERAGE('Survey Results'!AK73,'Survey Results'!BS73,'Survey Results'!DA73,'Survey Results'!EI73,'Survey Results'!FQ73,'Survey Results'!GY73) -> 3.2415344
A7: Run AVG (GROUPED TEAMS AND INDIVIDUAL PROLIFIC) | C7: =AVERAGE('Survey Results'!E74,'Survey Results'!AM74,'Survey Results'!BU74,'Survey Results'!DC74,'Survey Results'!EK74,'Survey Results'!FS74,'Survey Results'!HA74,'Survey Results'!IF74,'Survey Results'!JK74,'Survey Results'!KP74,'Survey Results'!LU74,'Survey Results'!MZ74,'Survey Results'!OE74,'Survey Results'!PJ74,'Survey Results'!QO74,'Survey Results'!RT74,'Survey Results'!SY74,'Survey Results'!UD74,'Survey Results'!VI74,'Survey Results'!WN74,'Survey Results'!XS74,'Survey Results'!YX74,'Survey Results'!AAC74,'Survey Results'!ABH74,'Survey Results'!ACM74,'Survey Results'!ADR74,'Survey Results'!AEW74,'Survey Results'!AGB74,'Survey Results'!AHG74,'Survey Results'!AIL74,'Survey Results'!AJQ74,'Survey Results'!AKV74,'Survey Results'!AMA74,'Survey Results'!ANF74,'Survey Results'!AOK74) -> 1.6136656 | D7: =AVERAGE('Survey Results'!F74,'Survey Results'!AN74,'Survey Results'!BV74,'Survey Results'!DD74,'Survey Results'!EL74,'Survey Results'!FT74,'Survey Results'!HB74,'Survey Results'!IG74,'Survey Results'!JL74,'Survey Results'!KQ74,'Survey Results'!LV74,'Survey Results'!NA74,'Survey Results'!OF74,'Survey Results'!PK74,'Survey Results'!QP74,'Survey Results'!RU74,'Survey Results'!SZ74,'Survey Results'!UE74,'Survey Results'!VJ74,'Survey Results'!WO74,'Survey Results'!XT74,'Survey Results'!YY74,'Survey Results'!AAD74,'Survey Results'!ABI74,'Survey Results'!ACN74,'Survey Results'!ADS74,'Survey Results'!AEX74,'Survey Results'!AGC74,'Survey Results'!AHH74,'Survey Results'!AIM74,'Survey Results'!AJR74,'Survey Results'!AKW74,'Survey Results'!AMB74,'Survey Results'!ANG74,'Survey Results'!AOL74) -> 3.3496677 | E7: =AVERAGE('Survey Results'!G74,'Survey Results'!AO74,'Survey Results'!BW74,'Survey Results'!DE74,'Survey Results'!EM74,'Survey Results'!FU74,'Survey Results'!HC74,'Survey Results'!IH74,'Survey Results'!JM74,'Survey Results'!KR74,'Survey Results'!LW74,'Survey Results'!NB74,'Survey Results'!OG74,'Survey Results'!PL74,'Survey Results'!QQ74,'Survey Results'!RV74,'Survey Results'!TA74,'Survey Results'!UF74,'Survey Results'!VK74,'Survey Results'!WP74,'Survey Results'!XU74,'Survey Results'!YZ74,'Survey Results'!AAE74,'Survey Results'!ABJ74,'Survey Results'!ACO74,'Survey Results'!ADT74,'Survey Results'!AEY74,'Survey Results'!AGD74,'Survey Results'!AHI74,'Survey Results'!AIN74,'Survey Results'!AJS74,'Survey Results'!AKX74,'Survey Results'!AMC74,'Survey Results'!ANH74,'Survey Results'!AOM74) -> 3.4293328 | F7: =AVERAGE('Survey Results'!H74,'Survey Results'!AP74,'Survey Results'!BX74,'Survey Results'!DF74,'Survey Results'!EN74,'Survey Results'!FV74,'Survey Results'!HD74,'Survey Results'!II74,'Survey Results'!JN74,'Survey Results'!KS74,'Survey Results'!LX74,'Survey Results'!NC74,'Survey Results'!OH74,'Survey Results'!PM74,'Survey Results'!QR74,'Survey Results'!RW74,'Survey Results'!TB74,'Survey Results'!UG74,'Survey Results'!VL74,'Survey Results'!WQ74,'Survey Results'!XV74,'Survey Results'!ZA74,'Survey Results'!AAF74,'Survey Results'!ABK74,'Survey Results'!ACP74,'Survey Results'!ADU74,'Survey Results'!AEZ74,'Survey Results'!AGE74,'Survey Results'!AHJ74,'Survey Results'!AIO74,'Survey Results'!AJT74,'Survey Results'!AKY74,'Survey Results'!AMD74,'Survey Results'!ANI74,'Survey Results'!AON74) -> 3.5165437 | G7: =AVERAGE('Survey Results'!I74,'Survey Results'!AQ74,'Survey Results'!BY74,'Survey Results'!DG74,'Survey Results'!EO74,'Survey Results'!FW74,'Survey Results'!HE74,'Survey Results'!IJ74,'Survey Results'!JO74,'Survey Results'!KT74,'Survey Results'!LY74,'Survey Results'!ND74,'Survey Results'!OI74,'Survey Results'!PN74,'Survey Results'!QS74,'Survey Results'!RX74,'Survey Results'!TC74,'Survey Results'!UH74,'Survey Results'!VM74,'Survey Results'!WR74,'Survey Results'!XW74,'Survey Results'!ZB74,'Survey Results'!AAG74,'Survey Results'!ABL74,'Survey Results'!ACQ74,'Survey Results'!ADV74,'Survey Results'!AFA74,'Survey Results'!AGF74,'Survey Results'!AHK74,'Survey Results'!AIP74,'Survey Results'!AJU74,'Survey Results'!AKZ74,'Survey Results'!AME74,'Survey Results'!ANJ74,'Survey Results'!AOO74) -> 3.3624464 | H7: =AVERAGE('Survey Results'!J74,'Survey Results'!AR74,'Survey Results'!BZ74,'Survey Results'!DH74,'Survey Results'!EP74,'Survey Results'!FX74,'Survey Results'!HF74,'Survey Results'!IK74,'Survey Results'!JP74,'Survey Results'!KU74,'Survey Results'!LZ74,'Survey Results'!NE74,'Survey Results'!OJ74,'Survey Results'!PO74,'Survey Results'!QT74,'Survey Results'!RY74,'Survey Results'!TD74,'Survey Results'!UI74,'Survey Results'!VN74,'Survey Results'!WS74,'Survey Results'!XX74,'Survey Results'!ZC74,'Survey Results'!AAH74,'Survey Results'!ABM74,'Survey Results'!ACR74,'Survey Results'!ADW74,'Survey Results'!AFB74,'Survey Results'!AGG74,'Survey Results'!AHL74,'Survey Results'!AIQ74,'Survey Results'!AJV74,'Survey Results'!ALA74,'Survey Results'!AMF74,'Survey Results'!ANK74,'Survey Results'!AOP74) -> 3.4311722 | I7: =AVERAGE('Survey Results'!K74,'Survey Results'!AS74,'Survey Results'!CA74,'Survey Results'!DI74,'Survey Results'!EQ74,'Survey Results'!FY74,'Survey Results'!HG74,'Survey Results'!IL74,'Survey Results'!JQ74,'Survey Results'!KV74,'Survey Results'!MA74,'Survey Results'!NF74,'Survey Results'!OK74,'Survey Results'!PP74,'Survey Results'!QU74,'Survey Results'!RZ74,'Survey Results'!TE74,'Survey Results'!UJ74,'Survey Results'!VO74,'Survey Results'!WT74,'Survey Results'!XY74,'Survey Results'!ZD74,'Survey Results'!AAI74,'Survey Results'!ABN74,'Survey Results'!ACS74,'Survey Results'!ADX74,'Survey Results'!AFC74,'Survey Results'!AGH74,'Survey Results'!AHM74,'Survey Results'!AIR74,'Survey Results'!AJW74,'Survey Results'!ALB74,'Survey Results'!AMG74,'Survey Results'!ANL74,'Survey Results'!AOQ74) -> 3.3794113 | J7: =AVERAGE('Survey Results'!L74,'Survey Results'!AT74,'Survey Results'!CB74,'Survey Results'!DJ74,'Survey Results'!ER74,'Survey Results'!FZ74,'Survey Results'!HH74,'Survey Results'!IM74,'Survey Results'!JR74,'Survey Results'!KW74,'Survey Results'!MB74,'Survey Results'!NG74,'Survey Results'!OL74,'Survey Results'!PQ74,'Survey Results'!QV74,'Survey Results'!SA74,'Survey Results'!TF74,'Survey Results'!UK74,'Survey Results'!VP74,'Survey Results'!WU74,'Survey Results'!XZ74,'Survey Results'!ZE74,'Survey Results'!AAJ74,'Survey Results'!ABO74,'Survey Results'!ACT74,'Survey Results'!ADY74,'Survey Results'!AFD74,'Survey Results'!AGI74,'Survey Results'!AHN74,'Survey Results'!AIS74,'Survey Results'!AJX74,'Survey Results'!ALC74,'Survey Results'!AMH74,'Survey Results'!ANM74,'Survey Results'!AOR74) -> 3.6158111 | ... AF7: =AVERAGE('Survey Results'!AH74,'Survey Results'!BP74,'Survey Results'!CX74,'Survey Results'!EF74,'Survey Results'!FN74,'Survey Results'!GV74,'Survey Results'!ID74,'Survey Results'!JI74,'Survey Results'!KN74,'Survey Results'!LS74,'Survey Results'!MX74,'Survey Results'!OC74,'Survey Results'!PH74,'Survey Results'!QM74,'Survey Results'!RR74,'Survey Results'!SW74,'Survey Results'!UB74,'Survey Results'!VG74,'Survey Results'!WL74,'Survey Results'!XQ74,'Survey Results'!YV74,'Survey Results'!AAA74,'Survey Results'!ABF74,'Survey Results'!ACK74,'Survey Results'!ADP74,'Survey Results'!AEU74,'Survey Results'!AFZ74,'Survey Results'!AHE74,'Survey Results'!AIJ74,'Survey Results'!AJO74,'Survey Results'!AKT74,'Survey Results'!ALY74,'Survey Results'!AND74,'Survey Results'!AOI74,'Survey Results'!APN74) -> 3.2093354 | AG7: =AVERAGE('Survey Results'!AI74,'Survey Results'!BQ74,'Survey Results'!CY74,'Survey Results'!EG74,'Survey Results'!FO74,'Survey Results'!GW74) -> 3.0435226 | AH7: =AVERAGE('Survey Results'!AJ74,'Survey Results'!BR74,'Survey Results'!CZ74,'Survey Results'!EH74,'Survey Results'!FP74,'Survey Results'!GX74) -> 2.9897436 | AI7: =AVERAGE('Survey Results'!AK74,'Survey Results'!BS74,'Survey Results'!DA74,'Survey Results'!EI74,'Survey Results'!FQ74,'Survey Results'!GY74) -> 3.0850733
A8: DELTA | C8: =C5-C7 -> 0.076538462 | D8: =D5-D7 -> 0.15931188 | E8: =E5-E7 -> 0.1249529 | F8: =F5-F7 -> 0.098558346 | G8: =G5-G7 -> 0.11061486 | H8: =H5-H7 -> 0.13903192 | I8: =I5-I7 -> 0.12793564 | J8: =J5-J7 -> 0.076841968 | ... AI8: =AI5-AI7 -> 0.21076007
A10: Rank | B10: Group | C10: Run | D10: Score
A11: #1 | B11: CERTH-ITI | C11: Run 6 | D11: 3.6158111
A12: #2 | B12: FAST-MS | C12: RealVisXL | D12: 3.2093354
A13: #3 | B13: TEAM-A++ | C13: SDXL-CFT | D13: 3.0414103
A14: #4 | B14: NewsWeavers | C14: Qwen 3B Plan Prompt Zero Shot FLUX | D14: 2.9065725
B15: Baseline | C15: Originals | D15: 2.8797823
A16: #5 | B16: FAST-DS | C16: VisionAnchor | D16: 2.3900131
A17: #6 | B17: AIINS-11 | C17: PD12MTFIDF | D17: 1.6136656
A18: Groupes rankes by the score of their best run submission.

Sheet Survey Results
A1: Group Name | E1: AIINS-1 | F1: CERTH-ITI | G1: CERTH-ITI | H1: CERTH-ITI | I1: CERTH-ITI | J1: CERTH-ITI | K1: CERTH-ITI | L1: CERTH-ITI | M1: CERTH-ITI | N1: CERTH-ITI | O1: CERTH-ITI | P1: FAST-DS | Q1: FAST-DS | R1: FAST-DS | S1: FAST-DS | T1: FAST-DS | U1: FAST-DS | V1: FAST-MS | W1: FAST-MS | X1: FAST-MS | Y1: NewsWeavers | Z1: NewsWeavers | AA1: NewsWeavers | AB1: NewsWeavers | AC1: TEAM-A++ | AD1: UAmsterdam | AE1: UAmsterdam | AF1: UAmsterdam | AG1: BASELINE | AH1: FAST-MS | AI1: Insight | AJ1: Insight | AK1: Insight | AM1: AIINS-1 | AN1: CERTH-ITI | AO1: CERTH-ITI | AP1: CERTH-ITI | AQ1: CERTH-ITI | AR1: CERTH-ITI | AS1: CERTH-ITI | AT1: CERTH-ITI | AU1: CERTH-ITI | AV1: CERTH-ITI | AW1: CERTH-ITI | AX1: FAST-DS | AY1: FAST-DS | AZ1: FAST-DS | BA1: FAST-DS | BB1: FAST-DS | BC1: FAST-DS | BD1: FAST-MS | BE1: FAST-MS | BF1: FAST-MS | BG1: NewsWeavers | BH1: NewsWeavers | BI1: NewsWeavers | BJ1: NewsWeavers | BK1: TEAM-A++ | BL1: UAmsterdam | BM1: UAmsterdam | BN1: UAmsterdam | BO1: BASELINE | BP1: FAST-MS | BQ1: Insight | BR1: Insight | BS1: Insight | BU1: AIINS-1 | BV1: CERTH-ITI | BW1: CERTH-ITI | BX1: CERTH-ITI | BY1: CERTH-ITI | BZ1: CERTH-ITI | CA1: CERTH-ITI | CB1: CERTH-ITI | CC1: CERTH-ITI | CD1: CERTH-ITI | CE1: CERTH-ITI | CF1: FAST-DS | CG1: FAST-DS | CH1: FAST-DS | CI1: FAST-DS | CJ1: FAST-DS | CK1: FAST-DS | CL1: FAST-MS | CM1: FAST-MS | CN1: FAST-MS | CO1: NewsWeavers | CP1: NewsWeavers | CQ1: NewsWeavers | CR1: NewsWeavers | CS1: TEAM-A++ | CT1: UAmsterdam | CU1: UAmsterdam | CV1: UAmsterdam | CW1: BASELINE | CX1: FAST-MS | CY1: Insight | CZ1: Insight | DA1: Insight | DC1: AIINS-1 | DD1: CERTH-ITI | DE1: CERTH-ITI | DF1: CERTH-ITI | DG1: CERTH-ITI | DH1: CERTH-ITI | DI1: CERTH-ITI | DJ1: CERTH-ITI | DK1: CERTH-ITI | DL1: CERTH-ITI | DM1: CERTH-ITI | DN1: FAST-DS | DO1: FAST-DS | DP1: FAST-DS | DQ1: FAST-DS | DR1: FAST-DS | DS1: FAST-DS | DT1: FAST-MS | DU1: FAST-MS | DV1: FAST-MS | DW1: NewsWeavers | DX1: NewsWeavers | DY1: NewsWeavers | DZ1: NewsWeavers | EA1: TEAM-A++ | EB1: UAmsterdam | EC1: UAmsterdam | ED1: UAmsterdam | EE1: BASELINE | EF1: FAST-MS | EG1: Insight | EH1: Insight | EI1: Insight | EK1: AIINS-1 | EL1: CERTH-ITI | EM1: CERTH-ITI | EN1: CERTH-ITI | EO1: CERTH-ITI | EP1: CERTH-ITI | EQ1: CERTH-ITI | ER1: CERTH-ITI | ES1: CERTH-ITI | ET1: CERTH-ITI | EU1: CERTH-ITI | EV1: FAST-DS | EW1: FAST-DS | EX1: FAST-DS | EY1: FAST-DS | EZ1: FAST-DS | FA1: FAST-DS | FB1: FAST-MS | FC1: FAST-MS | FD1: FAST-MS | FE1: NewsWeavers | FF1: NewsWeavers | FG1: NewsWeavers | FH1: NewsWeavers | FI1: TEAM-A++ | FJ1: UAmsterdam | FK1: UAmsterdam | FL1: UAmsterdam | FM1: BASELINE | FN1: FAST-MS | FO1: Insight | FP1: Insight | FQ1: Insight | FS1: AIINS-1 | FT1: CERTH-ITI | FU1: CERTH-ITI | FV1: CERTH-ITI | FW1: CERTH-ITI | FX1: CERTH-ITI | FY1: CERTH-ITI | FZ1: CERTH-ITI | GA1: CERTH-ITI | GB1: CERTH-ITI | GC1: CERTH-ITI | GD1: FAST-DS | GE1: FAST-DS | GF1: FAST-DS | GG1: FAST-DS | GH1: FAST-DS | GI1: FAST-DS | GJ1: FAST-MS | GK1: FAST-MS | GL1: FAST-MS | GM1: NewsWeavers | GN1: NewsWeavers | GO1: NewsWeavers | GP1: NewsWeavers | GQ1: TEAM-A++ | GR1: UAmsterdam | GS1: UAmsterdam | GT1: UAmsterdam | GU1: BASELINE | GV1: FAST-MS | GW1: Insight | GX1: Insight | GY1: Insight | HA1: AIINS-1 | HB1: CERTH-ITI | HC1: CERTH-ITI | HD1: CERTH-ITI | HE1: CERTH-ITI | HF1: CERTH-ITI | HG1: CERTH-ITI | HH1: CERTH-ITI | HI1: CERTH-ITI | HJ1: CERTH-ITI | HK1: CERTH-ITI | HL1: FAST-DS | HM1: FAST-DS | HN1: FAST-DS | HO1: FAST-DS | HP1: FAST-DS | HQ1: FAST-DS | HR1: FAST-MS | HS1: FAST-MS | HT1: FAST-MS | HU1: NewsWeavers | HV1: NewsWeavers | HW1: NewsWeavers | HX1: NewsWeavers | HY1: TEAM-A++ | HZ1: UAmsterdam | IA1: UAmsterdam | IB1: UAmsterdam | IC1: BASELINE | ID1: FAST-MS | IF1: AIINS-1 | IG1: CERTH-ITI | IH1: CERTH-ITI | II1: CERTH-ITI | IJ1: CERTH-ITI | IK1: CERTH-ITI | IL1: CERTH-ITI | IM1: CERTH-ITI | IN1: CERTH-ITI | IO1: CERTH-ITI | IP1: CERTH-ITI | IQ1: FAST-DS | IR1: FAST-DS | IS1: FAST-DS | IT1: FAST-DS | IU1: FAST-DS | IV1: FAST-DS | IW1: FAST-MS | IX1: FAST-MS | IY1: FAST-MS | IZ1: NewsWeavers | JA1: NewsWeavers | JB1: NewsWeavers | JC1: NewsWeavers | JD1: TEAM-A++ | JE1: UAmsterdam | JF1: UAmsterdam | JG1: UAmsterdam | JH1: BASELINE | JI1: FAST-MS | JK1: AIINS-1 | JL1: CERTH-ITI | JM1: CERTH-ITI | JN1: CERTH-ITI | JO1: CERTH-ITI | JP1: CERTH-ITI | JQ1: CERTH-ITI | JR1: CERTH-ITI | JS1: CERTH-ITI | JT1: CERTH-ITI | JU1: CERTH-ITI | JV1: FAST-DS | JW1: FAST-DS | JX1: FAST-DS | JY1: FAST-DS | JZ1: FAST-DS | KA1: FAST-DS | KB1: FAST-MS | KC1: FAST-MS | KD1: FAST-MS | KE1: NewsWeavers | KF1: NewsWeavers | KG1: NewsWeavers | KH1: NewsWeavers | KI1: TEAM-A++ | KJ1: UAmsterdam | KK1: UAmsterdam | KL1: UAmsterdam | KM1: BASELINE | KN1: FAST-MS | KP1: AIINS-1 | KQ1: CERTH-ITI | KR1: CERTH-ITI | KS1: CERTH-ITI | KT1: CERTH-ITI | KU1: CERTH-ITI | KV1: CERTH-ITI | KW1: CERTH-ITI | KX1: CERTH-ITI | KY1: CERTH-ITI | KZ1: CERTH-ITI | LA1: FAST-DS | LB1: FAST-DS | LC1: FAST-DS | LD1: FAST-DS | LE1: FAST-DS | LF1: FAST-DS | LG1: FAST-MS | LH1: FAST-MS | LI1: FAST-MS | LJ1: NewsWeavers | LK1: NewsWeavers | LL1: NewsWeavers | LM1: NewsWeavers | LN1: TEAM-A++ | LO1: UAmsterdam | LP1: UAmsterdam | LQ1: UAmsterdam | LR1: BASELINE | LS1: FAST-MS | LU1: AIINS-1 | LV1: CERTH-ITI | LW1: CERTH-ITI | LX1: CERTH-ITI | LY1: CERTH-ITI | LZ1: CERTH-ITI | MA1: CERTH-ITI | MB1: CERTH-ITI | MC1: CERTH-ITI | MD1: CERTH-ITI | ME1: CERTH-ITI | MF1: FAST-DS | MG1: FAST-DS | MH1: FAST-DS | MI1: FAST-DS | MJ1: FAST-DS | MK1: FAST-DS | ML1: FAST-MS | MM1: FAST-MS | MN1: FAST-MS | MO1: NewsWeavers | MP1: NewsWeavers | MQ1: NewsWeavers | MR1: NewsWeavers | MS1: TEAM-A++ | MT1: UAmsterdam | MU1: UAmsterdam | MV1: UAmsterdam | MW1: BASELINE | MX1: FAST-MS | MZ1: AIINS-1 | NA1: CERTH-ITI | NB1: CERTH-ITI | NC1: CERTH-ITI | ND1: CERTH-ITI | NE1: CERTH-ITI | NF1: CERTH-ITI | NG1: CERTH-ITI | NH1: CERTH-ITI | NI1: CERTH-ITI | NJ1: CERTH-ITI | NK1: FAST-DS | NL1: FAST-DS | NM1: FAST-DS | NN1: FAST-DS | NO1: FAST-DS | NP1: FAST-DS | NQ1: FAST-MS | NR1: FAST-MS | NS1: FAST-MS | NT1: NewsWeavers | NU1: NewsWeavers | NV1: NewsWeavers | NW1: NewsWeavers | NX1: TEAM-A++ | NY1: UAmsterdam | NZ1: UAmsterdam | OA1: UAmsterdam | OB1: BASELINE | OC1: FAST-MS | OE1: AIINS-1 | OF1: CERTH-ITI | OG1: CERTH-ITI | OH1: CERTH-ITI | OI1: CERTH-ITI | OJ1: CERTH-ITI | OK1: CERTH-ITI | OL1: CERTH-ITI | OM1: CERTH-ITI | ON1: CERTH-ITI | OO1: CERTH-ITI | OP1: FAST-DS | OQ1: FAST-DS | OR1: FAST-DS | OS1: FAST-DS | OT1: FAST-DS | OU1: FAST-DS | OV1: FAST-MS | OW1: FAST-MS | OX1: FAST-MS | OY1: NewsWeavers | OZ1: NewsWeavers | PA1: NewsWeavers | PB1: NewsWeavers | PC1: TEAM-A++ | PD1: UAmsterdam | PE1: UAmsterdam | PF1: UAmsterdam | PG1: BASELINE | PH1: FAST-MS | PJ1: AIINS-1 | PK1: CERTH-ITI | PL1: CERTH-ITI | PM1: CERTH-ITI | PN1: CERTH-ITI | PO1: CERTH-ITI | PP1: CERTH-ITI | PQ1: CERTH-ITI | PR1: CERTH-ITI | PS1: CERTH-ITI | PT1: CERTH-ITI | PU1: FAST-DS | PV1: FAST-DS | PW1: FAST-DS | PX1: FAST-DS | PY1: FAST-DS | PZ1: FAST-DS | QA1: FAST-MS | QB1: FAST-MS | QC1: FAST-MS | QD1: NewsWeavers | QE1: NewsWeavers | QF1: NewsWeavers | QG1: NewsWeavers | QH1: TEAM-A++ | QI1: UAmsterdam | QJ1: UAmsterdam | QK1: UAmsterdam | QL1: BASELINE | QM1: FAST-MS | QO1: AIINS-1 | QP1: CERTH-ITI | QQ1: CERTH-ITI | QR1: CERTH-ITI | QS1: CERTH-ITI | QT1: CERTH-ITI | QU1: CERTH-ITI | QV1: CERTH-ITI | QW1: CERTH-ITI | QX1: CERTH-ITI | QY1: CERTH-ITI | QZ1: FAST-DS | RA1: FAST-DS | RB1: FAST-DS | RC1: FAST-DS | RD1: FAST-DS | RE1: FAST-DS | RF1: FAST-MS | RG1: FAST-MS | RH1: FAST-MS | RI1: NewsWeavers | RJ1: NewsWeavers | RK1: NewsWeavers | RL1: NewsWeavers | RM1: TEAM-A++ | RN1: UAmsterdam | RO1: UAmsterdam | RP1: UAmsterdam | RQ1: BASELINE | RR1: FAST-MS | RT1: AIINS-1 | RU1: CERTH-ITI | RV1: CERTH-ITI | RW1: CERTH-ITI | RX1: CERTH-ITI | RY1: CERTH-ITI | RZ1: CERTH-ITI | SA1: CERTH-ITI | SB1: CERTH-ITI | SC1: CERTH-ITI | SD1: CERTH-ITI | SE1: FAST-DS | SF1: FAST-DS | SG1: FAST-DS | SH1: FAST-DS | SI1: FAST-DS | SJ1: FAST-DS | SK1: FAST-MS | SL1: FAST-MS | SM1: FAST-MS | SN1: NewsWeavers | SO1: NewsWeavers | SP1: NewsWeavers | SQ1: NewsWeavers | SR1: TEAM-A++ | SS1: UAmsterdam | ST1: UAmsterdam | SU1: UAmsterdam | SV1: BASELINE | SW1: FAST-MS | SY1: AIINS-1 | SZ1: CERTH-ITI | TA1: CERTH-ITI | TB1: CERTH-ITI | TC1: CERTH-ITI | TD1: CERTH-ITI | TE1: CERTH-ITI | TF1: CERTH-ITI | TG1: CERTH-ITI | TH1: CERTH-ITI | TI1: CERTH-ITI | TJ1: FAST-DS | TK1: FAST-DS | TL1: FAST-DS | TM1: FAST-DS | TN1: FAST-DS | TO1: FAST-DS | TP1: FAST-MS | TQ1: FAST-MS | TR1: FAST-MS | TS1: NewsWeavers | TT1: NewsWeavers | TU1: NewsWeavers | TV1: NewsWeavers | TW1: TEAM-A++ | TX1: UAmsterdam | TY1: UAmsterdam | TZ1: UAmsterdam | UA1: BASELINE | UB1: FAST-MS | UD1: AIINS-1 | UE1: CERTH-ITI | UF1: CERTH-ITI | UG1: CERTH-ITI | UH1: CERTH-ITI | UI1: CERTH-ITI | UJ1: CERTH-ITI | UK1: CERTH-ITI | UL1: CERTH-ITI | UM1: CERTH-ITI | UN1: CERTH-ITI | UO1: FAST-DS | UP1: FAST-DS | UQ1: FAST-DS | UR1: FAST-DS | US1: FAST-DS | UT1: FAST-DS | UU1: FAST-MS | UV1: FAST-MS | UW1: FAST-MS | UX1: NewsWeavers | UY1: NewsWeavers | UZ1: NewsWeavers | VA1: NewsWeavers | VB1: TEAM-A++ | VC1: UAmsterdam | VD1: UAmsterdam | VE1: UAmsterdam | VF1: BASELINE | VG1: FAST-MS | VI1: AIINS-1 | VJ1: CERTH-ITI | VK1: CERTH-ITI | VL1: CERTH-ITI | VM1: CERTH-ITI | VN1: CERTH-ITI | VO1: CERTH-ITI | VP1: CERTH-ITI | VQ1: CERTH-ITI | VR1: CERTH-ITI | VS1: CERTH-ITI | VT1: FAST-DS | VU1: FAST-DS | VV1: FAST-DS | VW1: FAST-DS | VX1: FAST-DS | VY1: FAST-DS | VZ1: FAST-MS | WA1: FAST-MS | WB1: FAST-MS | WC1: NewsWeavers | WD1: NewsWeavers | WE1: NewsWeavers | WF1: NewsWeavers | WG1: TEAM-A++ | WH1: UAmsterdam | WI1: UAmsterdam | WJ1: UAmsterdam | WK1: BASELINE | WL1: FAST-MS | WN1: AIINS-1 | WO1: CERTH-ITI | WP1: CERTH-ITI | WQ1: CERTH-ITI | WR1: CERTH-ITI | WS1: CERTH-ITI | WT1: CERTH-ITI | WU1: CERTH-ITI | WV1: CERTH-ITI | WW1: CERTH-ITI | WX1: CERTH-ITI | WY1: FAST-DS | WZ1: FAST-DS | XA1: FAST-DS | XB1: FAST-DS | XC1: FAST-DS | XD1: FAST-DS | XE1: FAST-MS | XF1: FAST-MS | XG1: FAST-MS | XH1: NewsWeavers | XI1: NewsWeavers | XJ1: NewsWeavers | XK1: NewsWeavers | XL1: TEAM-A++ | XM1: UAmsterdam | XN1: UAmsterdam | XO1: UAmsterdam | XP1: BASELINE | XQ1: FAST-MS | XS1: AIINS-1 | XT1: CERTH-ITI | XU1: CERTH-ITI | XV1: CERTH-ITI | XW1: CERTH-ITI | XX1: CERTH-ITI | XY1: CERTH-ITI | XZ1: CERTH-ITI | YA1: CERTH-ITI | YB1: CERTH-ITI | YC1: CERTH-ITI | YD1: FAST-DS | YE1: FAST-DS | YF1: FAST-DS | YG1: FAST-DS | YH1: FAST-DS | YI1: FAST-DS | YJ1: FAST-MS | YK1: FAST-MS | YL1: FAST-MS | YM1: NewsWeavers | YN1: NewsWeavers | YO1: NewsWeavers | YP1: NewsWeavers | YQ1: TEAM-A++ | YR1: UAmsterdam | YS1: UAmsterdam | YT1: UAmsterdam | YU1: BASELINE | YV1: FAST-MS | YX1: AIINS-1 | YY1: CERTH-ITI | YZ1: CERTH-ITI | ZA1: CERTH-ITI | ZB1: CERTH-ITI | ZC1: CERTH-ITI | ZD1: CERTH-ITI | ZE1: CERTH-ITI | ZF1: CERTH-ITI | ZG1: CERTH-ITI | ZH1: CERTH-ITI | ZI1: FAST-DS | ZJ1: FAST-DS | ZK1: FAST-DS | ZL1: FAST-DS | ZM1: FAST-DS | ZN1: FAST-DS | ZO1: FAST-MS | ZP1: FAST-MS | ZQ1: FAST-MS | ZR1: NewsWeavers | ZS1: NewsWeavers | ZT1: NewsWeavers | ZU1: NewsWeavers | ZV1: TEAM-A++ | ZW1: UAmsterdam | ZX1: UAmsterdam | ZY1: UAmsterdam | ZZ1: BASELINE | AAA1: FAST-MS | AAC1: AIINS-1 | AAD1: CERTH-ITI | AAE1: CERTH-ITI | AAF1: CERTH-ITI | AAG1: CERTH-ITI | AAH1: CERTH-ITI | AAI1: CERTH-ITI | AAJ1: CERTH-ITI | AAK1: CERTH-ITI | AAL1: CERTH-ITI | AAM1: CERTH-ITI | AAN1: FAST-DS | AAO1: FAST-DS | AAP1: FAST-DS | AAQ1: FAST-DS | AAR1: FAST-DS | AAS1: FAST-DS | AAT1: FAST-MS | AAU1: FAST-MS | AAV1: FAST-MS | AAW1: NewsWeavers | AAX1: NewsWeavers | AAY1: NewsWeavers | AAZ1: NewsWeavers | ABA1: TEAM-A++ | ABB1: UAmsterdam | ABC1: UAmsterdam | ABD1: UAmsterdam | ABE1: BASELINE | ABF1: FAST-MS | ABH1: AIINS-1 | ABI1: CERTH-ITI | ABJ1: CERTH-ITI | ABK1: CERTH-ITI | ABL1: CERTH-ITI | ABM1: CERTH-ITI | ABN1: CERTH-ITI | ABO1: CERTH-ITI | ABP1: CERTH-ITI | ABQ1: CERTH-ITI | ABR1: CERTH-ITI | ABS1: FAST-DS | ABT1: FAST-DS | ABU1: FAST-DS | ABV1: FAST-DS | ABW1: FAST-DS | ABX1: FAST-DS | ABY1: FAST-MS | ABZ1: FAST-MS | ACA1: FAST-MS | ACB1: NewsWeavers | ACC1: NewsWeavers | ACD1: NewsWeavers | ACE1: NewsWeavers | ACF1: TEAM-A++ | ACG1: UAmsterdam | ACH1: UAmsterdam | ACI1: UAmsterdam | ACJ1: BASELINE | ACK1: FAST-MS | ACM1: AIINS-1 | ACN1: CERTH-ITI | ACO1: CERTH-ITI | ACP1: CERTH-ITI | ACQ1: CERTH-ITI | ACR1: CERTH-ITI | ACS1: CERTH-ITI | ACT1: CERTH-ITI | ACU1: CERTH-ITI | ACV1: CERTH-ITI | ACW1: CERTH-ITI | ACX1: FAST-DS | ACY1: FAST-DS | ACZ1: FAST-DS | ADA1: FAST-DS | ADB1: FAST-DS | ADC1: FAST-DS | ADD1: FAST-MS | ADE1: FAST-MS | ADF1: FAST-MS | ADG1: NewsWeavers | ADH1: NewsWeavers | ADI1: NewsWeavers | ADJ1: NewsWeavers | ADK1: TEAM-A++ | ADL1: UAmsterdam | ADM1: UAmsterdam | ADN1: UAmsterdam | ADO1: BASELINE | ADP1: FAST-MS | ADR1: AIINS-1 | ADS1: CERTH-ITI | ADT1: CERTH-ITI | ADU1: CERTH-ITI | ADV1: CERTH-ITI | ADW1: CERTH-ITI | ADX1: CERTH-ITI | ADY1: CERTH-ITI | ADZ1: CERTH-ITI | AEA1: CERTH-ITI | AEB1: CERTH-ITI | AEC1: FAST-DS | AED1: FAST-DS | AEE1: FAST-DS | AEF1: FAST-DS | AEG1: FAST-DS | AEH1: FAST-DS | AEI1: FAST-MS | AEJ1: FAST-MS | AEK1: FAST-MS | AEL1: NewsWeavers | AEM1: NewsWeavers | AEN1: NewsWeavers | AEO1: NewsWeavers | AEP1: TEAM-A++ | AEQ1: UAmsterdam | AER1: UAmsterdam | AES1: UAmsterdam | AET1: BASELINE | AEU1: FAST-MS | AEW1: AIINS-1 | AEX1: CERTH-ITI | AEY1: CERTH-ITI | AEZ1: CERTH-ITI | AFA1: CERTH-ITI | AFB1: CERTH-ITI | AFC1: CERTH-ITI | AFD1: CERTH-ITI | AFE1: CERTH-ITI | AFF1: CERTH-ITI | AFG1: CERTH-ITI | AFH1: FAST-DS | AFI1: FAST-DS | AFJ1: FAST-DS | AFK1: FAST-DS | AFL1: FAST-DS | AFM1: FAST-DS | AFN1: FAST-MS | AFO1: FAST-MS | AFP1: FAST-MS | AFQ1: NewsWeavers | AFR1: NewsWeavers | AFS1: NewsWeavers | AFT1: NewsWeavers | AFU1: TEAM-A++ | AFV1: UAmsterdam | AFW1: UAmsterdam | AFX1: UAmsterdam | AFY1: BASELINE | AFZ1: FAST-MS | AGB1: AIINS-1 | AGC1: CERTH-ITI | AGD1: CERTH-ITI | AGE1: CERTH-ITI | AGF1: CERTH-ITI | AGG1: CERTH-ITI | AGH1: CERTH-ITI | AGI1: CERTH-ITI | AGJ1: CERTH-ITI | AGK1: CERTH-ITI | AGL1: CERTH-ITI | AGM1: FAST-DS | AGN1: FAST-DS | AGO1: FAST-DS | AGP1: FAST-DS | AGQ1: FAST-DS | AGR1: FAST-DS | AGS1: FAST-MS | AGT1: FAST-MS | AGU1: FAST-MS | AGV1: NewsWeavers | AGW1: NewsWeavers | AGX1: NewsWeavers | AGY1: NewsWeavers | AGZ1: TEAM-A++ | AHA1: UAmsterdam | AHB1: UAmsterdam | AHC1: UAmsterdam | AHD1: BASELINE | AHE1: FAST-MS | AHG1: AIINS-1 | AHH1: CERTH-ITI | AHI1: CERTH-ITI | AHJ1: CERTH-ITI | AHK1: CERTH-ITI | AHL1: CERTH-ITI | AHM1: CERTH-ITI | AHN1: CERTH-ITI | AHO1: CERTH-ITI | AHP1: CERTH-ITI | AHQ1: CERTH-ITI | AHR1: FAST-DS | AHS1: FAST-DS | AHT1: FAST-DS | AHU1: FAST-DS | AHV1: FAST-DS | AHW1: FAST-DS | AHX1: FAST-MS | AHY1: FAST-MS | AHZ1: FAST-MS | AIA1: NewsWeavers | AIB1: NewsWeavers | AIC1: NewsWeavers | AID1: NewsWeavers | AIE1: TEAM-A++ | AIF1: UAmsterdam | AIG1: UAmsterdam | AIH1: UAmsterdam | AII1: BASELINE | AIJ1: FAST-MS | AIL1: AIINS-1 | AIM1: CERTH-ITI | AIN1: CERTH-ITI | AIO1: CERTH-ITI | AIP1: CERTH-ITI | AIQ1: CERTH-ITI | AIR1: CERTH-ITI | AIS1: CERTH-ITI | AIT1: CERTH-ITI | AIU1: CERTH-ITI | AIV1: CERTH-ITI | AIW1: FAST-DS | AIX1: FAST-DS | AIY1: FAST-DS | AIZ1: FAST-DS | AJA1: FAST-DS | AJB1: FAST-DS | AJC1: FAST-MS | AJD1: FAST-MS | AJE1: FAST-MS | AJF1: NewsWeavers | AJG1: NewsWeavers | AJH1: NewsWeavers | AJI1: NewsWeavers | AJJ1: TEAM-A++ | AJK1: UAmsterdam | AJL1: UAmsterdam | AJM1: UAmsterdam | AJN1: BASELINE | AJO1: FAST-MS | AJQ1: AIINS-1 | AJR1: CERTH-ITI | AJS1: CERTH-ITI | AJT1: CERTH-ITI | AJU1: CERTH-ITI | AJV1: CERTH-ITI | AJW1: CERTH-ITI | AJX1: CERTH-ITI | AJY1: CERTH-ITI | AJZ1: CERTH-ITI | AKA1: CERTH-ITI | AKB1: FAST-DS | AKC1: FAST-DS | AKD1: FAST-DS | AKE1: FAST-DS | AKF1: FAST-DS | AKG1: FAST-DS | AKH1: FAST-MS | AKI1: FAST-MS | AKJ1: FAST-MS | AKK1: NewsWeavers | AKL1: NewsWeavers | AKM1: NewsWeavers | AKN1: NewsWeavers | AKO1: TEAM-A++ | AKP1: UAmsterdam | AKQ1: UAmsterdam | AKR1: UAmsterdam | AKS1: BASELINE | AKT1: FAST-MS | AKV1: AIINS-1 | AKW1: CERTH-ITI | AKX1: CERTH-ITI | AKY1: CERTH-ITI | AKZ1: CERTH-ITI | ALA1: CERTH-ITI | ALB1: CERTH-ITI | ALC1: CERTH-ITI | ALD1: CERTH-ITI | ALE1: CERTH-ITI | ALF1: CERTH-ITI | ALG1: FAST-DS | ALH1: FAST-DS | ALI1: FAST-DS | ALJ1: FAST-DS | ALK1: FAST-DS | ALL1: FAST-DS | ALM1: FAST-MS | ALN1: FAST-MS | ALO1: FAST-MS | ALP1: NewsWeavers | ALQ1: NewsWeavers | ALR1: NewsWeavers | ALS1: NewsWeavers | ALT1: TEAM-A++ | ALU1: UAmsterdam | ALV1: UAmsterdam | ALW1: UAmsterdam | ALX1: BASELINE | ALY1: FAST-MS | AMA1: AIINS-1 | AMB1: CERTH-ITI | AMC1: CERTH-ITI | AMD1: CERTH-ITI | AME1: CERTH-ITI | AMF1: CERTH-ITI | AMG1: CERTH-ITI | AMH1: CERTH-ITI | AMI1: CERTH-ITI | AMJ1: CERTH-ITI | AMK1: CERTH-ITI | AML1: FAST-DS | AMM1: FAST-DS | AMN1: FAST-DS | AMO1: FAST-DS | AMP1: FAST-DS | AMQ1: FAST-DS | AMR1: FAST-MS | AMS1: FAST-MS | AMT1: FAST-MS | AMU1: NewsWeavers | AMV1: NewsWeavers | AMW1: NewsWeavers | AMX1: NewsWeavers | AMY1: TEAM-A++ | AMZ1: UAmsterdam | ANA1: UAmsterdam | ANB1: UAmsterdam | ANC1: BASELINE | AND1: FAST-MS | ANF1: AIINS-1 | ANG1: CERTH-ITI | ANH1: CERTH-ITI | ANI1: CERTH-ITI | ANJ1: CERTH-ITI | ANK1: CERTH-ITI | ANL1: CERTH-ITI | ANM1: CERTH-ITI | ANN1: CERTH-ITI | ANO1: CERTH-ITI | ANP1: CERTH-ITI | ANQ1: FAST-DS | ANR1: FAST-DS | ANS1: FAST-DS | ANT1: FAST-DS | ANU1: FAST-DS | ANV1: FAST-DS | ANW1: FAST-MS | ANX1: FAST-MS | ANY1: FAST-MS | ANZ1: NewsWeavers | AOA1: NewsWeavers | AOB1: NewsWeavers | AOC1: NewsWeavers | AOD1: TEAM-A++ | AOE1: UAmsterdam | AOF1: UAmsterdam | AOG1: UAmsterdam | AOH1: BASELINE | AOI1: FAST-MS | AOK1: AIINS-1 | AOL1: CERTH-ITI | AOM1: CERTH-ITI | AON1: CERTH-ITI | AOO1: CERTH-ITI | AOP1: CERTH-ITI | AOQ1: CERTH-ITI | AOR1: CERTH-ITI | AOS1: CERTH-ITI | AOT1: CERTH-ITI | AOU1: CERTH-ITI | AOV1: FAST-DS | AOW1: FAST-DS | AOX1: FAST-DS | AOY1: FAST-DS | AOZ1: FAST-DS | APA1: FAST-DS | APB1: FAST-MS | APC1: FAST-MS | APD1: FAST-MS | APE1: NewsWeavers | APF1: NewsWeavers | APG1: NewsWeavers | APH1: NewsWeavers | API1: TEAM-A++ | APJ1: UAmsterdam | APK1: UAmsterdam | APL1: UAmsterdam | APM1: BASELINE | APN1: FAST-MS
