Workbook

Sheet News Articles 26
A1: article_id | B1: article_url | C1: article_title | D1: image_id
A2: 8501 | B2: https://resolver.kb.nl/resolve?urn=MMSAA06:165575032:mpeg21:p00001 | C2: The unveiling of the Iltis Monument in Shanghai. | D2: ff4fe3b12ab041cafc9b5655f3ec949e
A3: 8502 | B3: https://resolver.kb.nl/resolve?urn=MMSAA06:165575004:mpeg21:p00001 | C3: The demise of 'Burgundy'. | D3: 3d446f6d460b6c80ed8bb7eed7a608f3
A4: 8503 | B4: https://resolver.kb.nl/resolve?urn=MMSAA06:165575043:mpeg21:p00001 | C4: HH's visit MM. the queens at the Onze Lieve Vrouwe guesthouse. | D4: ecebad66d2b4fd4e7bbb2b97d57bb100
A5: 8504 | B5: https://resolver.kb.nl/resolve?urn=MMRHCE02:163620058:mpeg21:p00001 | C5: BENIGN DISEASE EISENHOWER'S CONDITION VERY SATISFACTORY | D5: 5bf04fd98212fe2e25fce8125247cc10
A6: 8505 | B6: https://resolver.kb.nl/resolve?urn=MMRHCE02:163620040:mpeg21:p00001 | C6: Three Thunderstreaks crashed over Gelderland. PILOTS ABLE TO SAVE THEMSELVES WITH EJECTION SEAT Lack of fuel | D6: 92c89d592e630ab686e72a8c3b96226e
A7: 8506 | B7: https://resolver.kb.nl/resolve?urn=MMRHCE02:163636034:mpeg21:p00001 | C7: Moscow against 'free airspace' KROESJEF DOES NOT CHANGE JUDGMENT ABOUT IKE US PRESIDENT TO RUSSIA? MOSCOW-WASHINGTON, May 12. | D7: fe269637ca212eaba179461c6e6570fa
A8: 8507 | B8: https://resolver.kb.nl/resolve?urn=MMRHCE02:163635070:mpeg21:p00001 | C8: Situation in South Africa still tense DEATH TOTAL RISE TO 66 JOHANNESBURG Cape Town, March 23 (Reuter A.P.). | D8: 93ad24f5fd48351a74dfe1ac691fdf20
A9: 8508 | B9: https://resolver.kb.nl/resolve?urn=ABCDDD:010814016:mpeg21:p001 | C9: Heavy fighting during Israeli punitive expedition in Jordan TWELVE HOURS OF WAR IN MIDDLE EAST TEL AVIV/AMMAN | D9: 084d9c4182d5568b0d8903e874894cf0
A10: 8509 | B10: https://resolver.kb.nl/resolve?urn=ABCDDD:010814041:mpeg21:p001 | C10: Johnson accepts surprising offer from government in Hanoi US AND ND-VIETNAM TO TALK HANOI, SAIGON, WASHINGTON (AP, UPI, Reuter) - President Johnson wants to make contact with representatives of North Vietnam, now that Hanoi is willing to talk. | D10: 97d549c5e67ccf8305999b2ff14387d5
A11: 8510 | B11: https://resolver.kb.nl/resolve?urn=ABCDDD:010814047:mpeg21:p001 | C11: SAIGON STRENGTHENS ARMY 'to prepare peace' | D11: c032a4cdc9beb794e1716b5e8303136d
A12: 8511 | B12: https://resolver.kb.nl/resolve?urn=ABCDDD:010880247:mpeg21:p001 | C12: Landslide French elections De Gaulle's great triumph: absolute majority | D12: dd01a756e57d52f9a86b53fed235c7fb
A13: 8512 | B13: https://resolver.kb.nl/resolve?urn=ABCDDD:010880263:mpeg21:p001 | C13: LETTER FROM WARSAW REJECTED Doebsek: we will continue | D13: b7bc7d667610be21b9799fe39ee86995
... A15181: 23680 | B15181: https://assets.msn.com/labs/mind/BBWzQEU.html | C15181: CNN reporter: This is the tense calm after protester shot | D15181: cff84d1b64094d84867ee5bcb64a7a87

Sheet Test
A1: article_id | B1: article_url | C1: article_title | D1: image_id
A2: 8501 | B2: N/A | C2: =VLOOKUP(A2,'News Articles 26'!$A$2:$D$15181,3) -> The unveiling of the Iltis Monument in Shanghai. | D2: N/A
A3: 8504 | B3: N/A | C3: =VLOOKUP(A3,'News Articles 26'!$A$2:$D$15181,3) -> BENIGN DISEASE EISENHOWER'S CONDITION VERY SATISFACTORY | D3: N/A
A4: 8509 | B4: N/A | C4: =VLOOKUP(A4,'News Articles 26'!$A$2:$D$15181,3) -> Johnson accepts surprising offer from government in Hanoi US AND ND-VIETNAM TO TALK HANOI, SAIGON, WASHINGTON (AP, UPI, Reuter) - President Johnson wants to make contact with representatives of North Vietnam, now that Hanoi is willing to talk. | D4: N/A
A5: 8511 | B5: N/A | C5: =VLOOKUP(A5,'News Articles 26'!$A$2:$D$15181,3) -> Landslide French elections De Gaulle's great triumph: absolute majority | D5: N/A
A6: 8516 | B6: N/A | C6: =VLOOKUP(A6,'News Articles 26'!$A$2:$D$15181,3) -> British-Dutch cooperation MARINE DEPLOYED ON OIL ROUTE Frigate patrol to Indian Ocean | D6: N/A
A7: 8517 | B7: N/A | C7: =VLOOKUP(A7,'News Articles 26'!$A$2:$D$15181,3) -> Chile turns to Russia Allende in Moscow for more help | D7: N/A
A8: 8519 | B8: N/A | C8: =VLOOKUP(A8,'News Articles 26'!$A$2:$D$15181,3) -> MORE THAN MILLION SPECTATORS Departure of Apollo 16 went smoothly | D8: N/A
A9: 8525 | B9: N/A | C9: =VLOOKUP(A9,'News Articles 26'!$A$2:$D$15181,3) -> RESISTANCE AGAINST KING GROWS Demonstrations for amnesty in Spain dispersed | D9: N/A
A10: 8526 | B10: N/A | C10: =VLOOKUP(A10,'News Articles 26'!$A$2:$D$15181,3) -> Fifty thousand demonstrators in Lisbon | D10: N/A
A11: 8527 | B11: N/A | C11: =VLOOKUP(A11,'News Articles 26'!$A$2:$D$15181,3) -> ECONOMIC PROBLEMS ARISING London is operating cautiously on the eve of the referendum. Unions are coming to their senses | D11: N/A
A12: 8528 | B12: N/A | C12: =VLOOKUP(A12,'News Articles 26'!$A$2:$D$15181,3) -> China concerned about the security of Western Europe | D12: N/A
A13: 8539 | B13: N/A | C13: =VLOOKUP(A13,'News Articles 26'!$A$2:$D$15181,3) -> China prepares Jimmy Carter a warm welcome | D13: N/A
... A801: 23663 | B801: N/A | C801: =VLOOKUP(A801,'News Articles 26'!$A$2:$D$15181,3) -> Portion of Parker Avenue under boil water advisory | D801: N/A

Sheet Evaluation
A1: article_id | B1: article_url | C1: article_title | D1: image_id
A2: ='News Articles 26'!A4 -> 8503 | B2: =IF(_xlfn.XLOOKUP(A2,Test!$A$2:$A$801,Test!$A$2:$A$801,0),"N/A",'News Articles 26'!B4) -> https://resolver.kb.nl/resolve?urn=MMSAA06:165575043:mpeg21:p00001 | C2: ='News Articles 26'!C4 -> HH's visit MM. the queens at the Onze Lieve Vrouwe guesthouse. | D2: =IF(B2="N/A","N/A",'News Articles 26'!D4) -> ecebad66d2b4fd4e7bbb2b97d57bb100
A3: ='News Articles 26'!A3 -> 8502 | B3: =IF(_xlfn.XLOOKUP(A3,Test!$A$2:$A$801,Test!$A$2:$A$801,0),"N/A",'News Articles 26'!B3) -> https://resolver.kb.nl/resolve?urn=MMSAA06:165575004:mpeg21:p00001 | C3: ='News Articles 26'!C3 -> The demise of 'Burgundy'. | D3: =IF(B3="N/A","N/A",'News Articles 26'!D3) -> 3d446f6d460b6c80ed8bb7eed7a608f3
A4: ='News Articles 26'!A7 -> 8506 | B4: =IF(_xlfn.XLOOKUP(A4,Test!$A$2:$A$801,Test!$A$2:$A$801,0),"N/A",'News Articles 26'!B7) -> https://resolver.kb.nl/resolve?urn=MMRHCE02:163636034:mpeg21:p00001 | C4: ='News Articles 26'!C7 -> Moscow against 'free airspace' KROESJEF DOES NOT CHANGE JUDGMENT ABOUT IKE US PRESIDENT TO RUSSIA? MOSCOW-WASHINGTON, May 12. | D4: =IF(B4="N/A","N/A",'News Articles 26'!D7) -> fe269637ca212eaba179461c6e6570fa
A5: ='News Articles 26'!A8 -> 8507 | B5: =IF(_xlfn.XLOOKUP(A5,Test!$A$2:$A$801,Test!$A$2:$A$801,0),"N/A",'News Articles 26'!B8) -> https://resolver.kb.nl/resolve?urn=MMRHCE02:163635070:mpeg21:p00001 | C5: ='News Articles 26'!C8 -> Situation in South Africa still tense DEATH TOTAL RISE TO 66 JOHANNESBURG Cape Town, March 23 (Reuter A.P.). | D5: =IF(B5="N/A","N/A",'News Articles 26'!D8) -> 93ad24f5fd48351a74dfe1ac691fdf20
A6: ='News Articles 26'!A6 -> 8505 | B6: =IF(_xlfn.XLOOKUP(A6,Test!$A$2:$A$801,Test!$A$2:$A$801,0),"N/A",'News Articles 26'!B6) -> https://resolver.kb.nl/resolve?urn=MMRHCE02:163620040:mpeg21:p00001 | C6: ='News Articles 26'!C6 -> Three Thunderstreaks crashed over Gelderland. PILOTS ABLE TO SAVE THEMSELVES WITH EJECTION SEAT Lack of fuel | D6: =IF(B6="N/A","N/A",'News Articles 26'!D6) -> 92c89d592e630ab686e72a8c3b96226e
A7: ='News Articles 26'!A34 -> 8533 | B7: =IF(_xlfn.XLOOKUP(A7,Test!$A$2:$A$801,Test!$A$2:$A$801,0),"N/A",'News Articles 26'!B34) -> https://resolver.kb.nl/resolve?urn=MMKB32:164680009:mpeg21:p00009 | C7: ='News Articles 26'!C34 -> THE VICTORIA THEATRE. | D7: =IF(B7="N/A","N/A",'News Articles 26'!D34) -> 9a0b6220034a069601e6fe5cc6cd5ad4
A8: ='News Articles 26'!A62 -> 8561 | B8: =IF(_xlfn.XLOOKUP(A8,Test!$A$2:$A$801,Test!$A$2:$A$801,0),"N/A",'News Articles 26'!B62) -> https://resolver.kb.nl/resolve?urn=MMKB19:000847039:mpeg21:p00001 | C8: ='News Articles 26'!C62 -> NATO conference opened by Pres. Eisenhower | D8: =IF(B8="N/A","N/A",'News Articles 26'!D62) -> 6adb248f59cfbb6e9756d48ae33f0bb4
A9: ='News Articles 26'!A87 -> 8586 | B9: =IF(_xlfn.XLOOKUP(A9,Test!$A$2:$A$801,Test!$A$2:$A$801,0),"N/A",'News Articles 26'!B87) -> https://resolver.kb.nl/resolve?urn=KBPERS01:003231022:mpeg21:p00018 | C9: ='News Articles 26'!C87 -> Dakar is not for fun. Westenberg and Van Eijk ride at full speed and finish | D9: =IF(B9="N/A","N/A",'News Articles 26'!D87) -> 97baa6ca582ba170e463291d77f0b431
A10: ='News Articles 26'!A86 -> 8585 | B10: =IF(_xlfn.XLOOKUP(A10,Test!$A$2:$A$801,Test!$A$2:$A$801,0),"N/A",'News Articles 26'!B86) -> https://resolver.kb.nl/resolve?urn=KBPERS01:003231022:mpeg21:p00011 | C10: ='News Articles 26'!C86 -> Waste is big business | D10: =IF(B10="N/A","N/A",'News Articles 26'!D86) -> d54bef148ed70d422503f1cd998b3a21
A11: ='News Articles 26'!A85 -> 8584 | B11: =IF(_xlfn.XLOOKUP(A11,Test!$A$2:$A$801,Test!$A$2:$A$801,0),"N/A",'News Articles 26'!B85) -> https://resolver.kb.nl/resolve?urn=KBPERS01:003231022:mpeg21:p00003 | C11: ='News Articles 26'!C85 -> Homeless people are 'talked into shelters' | D11: =IF(B11="N/A","N/A",'News Articles 26'!D85) -> 79fddac3e1b2bba8851848af46d9b004
A12: ='News Articles 26'!A83 -> 8582 | B12: =IF(_xlfn.XLOOKUP(A12,Test!$A$2:$A$801,Test!$A$2:$A$801,0),"N/A",'News Articles 26'!B83) -> https://resolver.kb.nl/resolve?urn=KBPERS01:003231013:mpeg21:p00007 | C12: ='News Articles 26'!C83 -> Putin visits Castro | D12: =IF(B12="N/A","N/A",'News Articles 26'!D83) -> 7b04b0a005c3ba3002e70adad799f4ac
A13: ='News Articles 26'!A82 -> 8581 | B13: =IF(_xlfn.XLOOKUP(A13,Test!$A$2:$A$801,Test!$A$2:$A$801,0),"N/A",'News Articles 26'!B82) -> https://resolver.kb.nl/resolve?urn=KBPERS01:003231013:mpeg21:p00006 | C13: ='News Articles 26'!C82 -> Fuel removed from Dodewaard without any problems | D13: =IF(B13="N/A","N/A",'News Articles 26'!D82) -> 19f920371fbc69882990d7629c35716d
A14: ='News Articles 26'!A81 -> 8580 | B14: =IF(_xlfn.XLOOKUP(A14,Test!$A$2:$A$801,Test!$A$2:$A$801,0),"N/A",'News Articles 26'!B81) -> https://resolver.kb.nl/resolve?urn=KBPERS01:003231013:mpeg21:p00003 | C14: ='News Articles 26'!C81 -> At least 100,000 hemp growers in the Netherlands | D14: =IF(B14="N/A","N/A",'News Articles 26'!D81) -> 7a8950a90728fa1707637eb3719497ef
A15: ='News Articles 26'!A79 -> 8578 | B15: =IF(_xlfn.XLOOKUP(A15,Test!$A$2:$A$801,Test!$A$2:$A$801,0),"N/A",'News Articles 26'!B79) -> https://resolver.kb.nl/resolve?urn=KBPERS01:003171014:mpeg21:p00013 | C15: ='News Articles 26'!C79 -> Still, fanfares at the commemoration of Marshall aid | D15: =IF(B15="N/A","N/A",'News Articles 26'!D79) -> 135586bebc9894cc13edfbedb590d29c
A16: ='News Articles 26'!A44 -> 8543 | B16: =IF(_xlfn.XLOOKUP(A16,Test!$A$2:$A$801,Test!$A$2:$A$801,0),"N/A",'News Articles 26'!B44) -> https://resolver.kb.nl/resolve?urn=KBPERS01:003165020:mpeg21:p00007 | C16: ='News Articles 26'!C44 -> Yeltsin dismisses government | D16: =IF(B16="N/A","N/A",'News Articles 26'!D44) -> bc2cb28e624cce38778cf8f04d3964df
A17: ='News Articles 26'!A58 -> 8557 | B17: =IF(_xlfn.XLOOKUP(A17,Test!$A$2:$A$801,Test!$A$2:$A$801,0),"N/A",'News Articles 26'!B58) -> https://resolver.kb.nl/resolve?urn=KBPERS01:003165009:mpeg21:p00008 | C17: ='News Articles 26'!C58 -> Many Chileans are not happy with Senator Pinochet | D17: =IF(B17="N/A","N/A",'News Articles 26'!D58) -> 423412ffdd72bdea2c77d9501fcdfdb6
A18: ='News Articles 26'!A57 -> 8556 | B18: =IF(_xlfn.XLOOKUP(A18,Test!$A$2:$A$801,Test!$A$2:$A$801,0),"N/A",'News Articles 26'!B57) -> https://resolver.kb.nl/resolve?urn=KBPERS01:003165009:mpeg21:p00001 | C18: ='News Articles 26'!C57 -> Jakarta police intervenes heavily in protests | D18: =IF(B18="N/A","N/A",'News Articles 26'!D57) -> 983e3771990f4604747c53c007b30bab
A19: ='News Articles 26'!A76 -> 8575 | B19: =IF(_xlfn.XLOOKUP(A19,Test!$A$2:$A$801,Test!$A$2:$A$801,0),"N/A",'News Articles 26'!B76) -> https://resolver.kb.nl/resolve?urn=KBPERS01:003161023:mpeg21:p00019 | C19: ='News Articles 26'!C76 -> WTC New York becomes leasing complex | D19: =IF(B19="N/A","N/A",'News Articles 26'!D76) -> 93c3719062504cd79cf9f2bb72d10f62
A20: ='News Articles 26'!A56 -> 8555 | B20: =IF(_xlfn.XLOOKUP(A20,Test!$A$2:$A$801,Test!$A$2:$A$801,0),"N/A",'News Articles 26'!B56) -> https://resolver.kb.nl/resolve?urn=KBPERS01:003159008:mpeg21:p00010 | C20: ='News Articles 26'!C56 -> "VW with Renault in heavy trucks" | D20: =IF(B20="N/A","N/A",'News Articles 26'!D56) -> f940294caba0780fe5eb4c79aedecfe4
A21: ='News Articles 26'!A55 -> 8554 | B21: =IF(_xlfn.XLOOKUP(A21,Test!$A$2:$A$801,Test!$A$2:$A$801,0),"N/A",'News Articles 26'!B55) -> https://resolver.kb.nl/resolve?urn=KBPERS01:003159008:mpeg21:p00009 | C21: ='News Articles 26'!C55 -> Market more balanced after supermarket merger | D21: =IF(B21="N/A","N/A",'News Articles 26'!D55) -> 30ae902e8733877cb177a910fc419f5d
A22: ='News Articles 26'!A61 -> 8560 | B22: =IF(_xlfn.XLOOKUP(A22,Test!$A$2:$A$801,Test!$A$2:$A$801,0),"N/A",'News Articles 26'!B61) -> https://resolver.kb.nl/resolve?urn=KBPERS01:003147011:mpeg21:p00005 | C22: ='News Articles 26'!C61 -> The clog is allowed on the work floor | D22: =IF(B22="N/A","N/A",'News Articles 26'!D61) -> 7fae3bec54118930d59f95cd83c0a7f5
A23: ='News Articles 26'!A60 -> 8559 | B23: =IF(_xlfn.XLOOKUP(A23,Test!$A$2:$A$801,Test!$A$2:$A$801,0),"N/A",'News Articles 26'!B60) -> https://resolver.kb.nl/resolve?urn=KBPERS01:003147006:mpeg21:p00013 | C23: ='News Articles 26'!C60 -> High time for European asylum policy | D23: =IF(B23="N/A","N/A",'News Articles 26'!D60) -> 62acfd6c317bd1fa9def63fa2f8f6f2c
A24: ='News Articles 26'!A54 -> 8553 | B24: =IF(_xlfn.XLOOKUP(A24,Test!$A$2:$A$801,Test!$A$2:$A$801,0),"N/A",'News Articles 26'!B54) -> https://resolver.kb.nl/resolve?urn=KBNRC01:000034634:mpeg21:p002 | C24: ='News Articles 26'!C54 -> IJ tunnel currently under construction over its full length | D24: =IF(B24="N/A","N/A",'News Articles 26'!D54) -> ef7a0e5b1c5ac5a8b27f0ee7920aca67
A25: ='News Articles 26'!A43 -> 8542 | B25: =IF(_xlfn.XLOOKUP(A25,Test!$A$2:$A$801,Test!$A$2:$A$801,0),"N/A",'News Articles 26'!B43) -> https://resolver.kb.nl/resolve?urn=KBNRC01:000031232:mpeg21:p006 | C25: ='News Articles 26'!C43 -> Bad weather hinders rehearsals for an open-air opera performance in Spanga. Mud and water fill the orchestra pit | D25: =IF(B25="N/A","N/A",'News Articles 26'!D43) -> d6efd93254dcaa45e86af90faf20559a
A26: ='News Articles 26'!A51 -> 8550 | B26: =IF(_xlfn.XLOOKUP(A26,Test!$A$2:$A$801,Test!$A$2:$A$801,0),"N/A",'News Articles 26'!B51) -> https://resolver.kb.nl/resolve?urn=KBNRC01:000029055:mpeg21:p003 | C26: ='News Articles 26'!C51 -> Installation of CPN mayor 'historic day' for Beerta | D26: =IF(B26="N/A","N/A",'News Articles 26'!D51) -> d988600c467a985bb10a84023e64ff1e
A27: ='News Articles 26'!A52 -> 8551 | B27: =IF(_xlfn.XLOOKUP(A27,Test!$A$2:$A$801,Test!$A$2:$A$801,0),"N/A",'News Articles 26'!B52) -> https://resolver.kb.nl/resolve?urn=KBNRC01:000029055:mpeg21:p003 | C27: ='News Articles 26'!C52 -> More than 2,000 stutterers are waiting for treatment for their speech impediment | D27: =IF(B27="N/A","N/A",'News Articles 26'!D52) -> 2f3dc1205da8b77a7ebf8e4ee1f8a95d
A28: ='News Articles 26'!A36 -> 8535 | B28: =IF(_xlfn.XLOOKUP(A28,Test!$A$2:$A$801,Test!$A$2:$A$801,0),"N/A",'News Articles 26'!B36) -> https://resolver.kb.nl/resolve?urn=KBNRC01:000028883:mpeg21:p007 | C28: ='News Articles 26'!C36 -> Cabinet cannot deny nor stop the political power of the elderly movement. The illusions of Lubbers' "caring society" | D28: =IF(B28="N/A","N/A",'News Articles 26'!D36) -> c2886321edf3e12a580e48717838d56a
A29: ='News Articles 26'!A35 -> 8534 | B29: =IF(_xlfn.XLOOKUP(A29,Test!$A$2:$A$801,Test!$A$2:$A$801,0),"N/A",'News Articles 26'!B35) -> https://resolver.kb.nl/resolve?urn=KBNRC01:000028883:mpeg21:p003 | C29: ='News Articles 26'!C35 -> Vondelkerk almost as new again | D29: =IF(B29="N/A","N/A",'News Articles 26'!D35) -> 7eaca616ec9bf1033bb8baed4424aea7
A30: ='News Articles 26'!A38 -> 8537 | B30: =IF(_xlfn.XLOOKUP(A30,Test!$A$2:$A$801,Test!$A$2:$A$801,0),"N/A",'News Articles 26'!B38) -> https://resolver.kb.nl/resolve?urn=KBNRC01:000028852:mpeg21:p002 | C30: ='News Articles 26'!C38 -> Coffee house resurrected from ruins | D30: =IF(B30="N/A","N/A",'News Articles 26'!D38) -> 461c0476e694d30691b4830b3817edce
A31: ='News Articles 26'!A37 -> 8536 | B31: =IF(_xlfn.XLOOKUP(A31,Test!$A$2:$A$801,Test!$A$2:$A$801,0),"N/A",'News Articles 26'!B37) -> https://resolver.kb.nl/resolve?urn=KBNRC01:000028840:mpeg21:p001 | C31: ='News Articles 26'!C37 -> Employment plan stumbling block Van Agt Cabinet offers resignation | D31: =IF(B31="N/A","N/A",'News Articles 26'!D37) -> c1f0e5f900eb4927f573c2573bdc7e03
A32: ='News Articles 26'!A41 -> 8540 | B32: =IF(_xlfn.XLOOKUP(A32,Test!$A$2:$A$801,Test!$A$2:$A$801,0),"N/A",'News Articles 26'!B41) -> https://resolver.kb.nl/resolve?urn=KBNRC01:000028505:mpeg21:p005 | C32: ='News Articles 26'!C41 -> Reagan Briefs Congress: Saudis Get Awacs | D32: =IF(B32="N/A","N/A",'News Articles 26'!D41) -> 29ccb1f0e4dd56a95d882ac6a905329f
A33: ='News Articles 26'!A39 -> 8538 | B33: =IF(_xlfn.XLOOKUP(A33,Test!$A$2:$A$801,Test!$A$2:$A$801,0),"N/A",'News Articles 26'!B39) -> https://resolver.kb.nl/resolve?urn=KBNRC01:000027391:mpeg21:p002 | C33: ='News Articles 26'!C39 -> Massive lawsuit threatens Jordaan landlords | D33: =IF(B33="N/A","N/A",'News Articles 26'!D39) -> ef2d773cc5bac4c46b75f7681a8ce001
A34: ='News Articles 26'!A53 -> 8552 | B34: =IF(_xlfn.XLOOKUP(A34,Test!$A$2:$A$801,Test!$A$2:$A$801,0),"N/A",'News Articles 26'!B53) -> https://resolver.kb.nl/resolve?urn=KBNRC01:000026915:mpeg21:p005 | C34: ='News Articles 26'!C53 -> Doubts in the US about the correctness of American Soviet policy | D34: =IF(B34="N/A","N/A",'News Articles 26'!D53) -> 363f49392d332a179c83cc6bea93782f
A35: ='News Articles 26'!A50 -> 8549 | B35: =IF(_xlfn.XLOOKUP(A35,Test!$A$2:$A$801,Test!$A$2:$A$801,0),"N/A",'News Articles 26'!B50) -> https://resolver.kb.nl/resolve?urn=KBNRC01:000026915:mpeg21:p004 | C35: ='News Articles 26'!C50 -> French-German top can talk about their own 'third way' for Western Europe | D35: =IF(B35="N/A","N/A",'News Articles 26'!D50) -> 545c20a559ffc50aaf86efb0c0a94c51
A36: ='News Articles 26'!A49 -> 8548 | B36: =IF(_xlfn.XLOOKUP(A36,Test!$A$2:$A$801,Test!$A$2:$A$801,0),"N/A",'News Articles 26'!B49) -> https://resolver.kb.nl/resolve?urn=KBNRC01:000026915:mpeg21:p003 | C36: ='News Articles 26'!C49 -> French 'objecteurs' ask for political asylum | D36: =IF(B36="N/A","N/A",'News Articles 26'!D49) -> 89e7bb4b80cd32da7acf233f2840b48c
A37: ='News Articles 26'!A32 -> 8531 | B37: =IF(_xlfn.XLOOKUP(A37,Test!$A$2:$A$801,Test!$A$2:$A$801,0),"N/A",'News Articles 26'!B32) -> https://resolver.kb.nl/resolve?urn=ddd:011198836:mpeg21:p003 | C37: ='News Articles 26'!C32 -> Holiday spread in jeopardy for coastal hotels. Tourist flow failed | D37: =IF(B37="N/A","N/A",'News Articles 26'!D32) -> 9853a0842854c38eb1efaf943c2ace04
A38: ='News Articles 26'!A31 -> 8530 | B38: =IF(_xlfn.XLOOKUP(A38,Test!$A$2:$A$801,Test!$A$2:$A$801,0),"N/A",'News Articles 26'!B31) -> https://resolver.kb.nl/resolve?urn=ddd:011198697:mpeg21:p001 | C38: ='News Articles 26'!C31 -> LIBYA HOLDS PROTOTYPE AND CREW Fokker team suspected of espionage | D38: =IF(B38="N/A","N/A",'News Articles 26'!D31) -> ee50742b6e07d29f5ddbdb88c3fa6f33
A39: ='News Articles 26'!A30 -> 8529 | B39: =IF(_xlfn.XLOOKUP(A39,Test!$A$2:$A$801,Test!$A$2:$A$801,0),"N/A",'News Articles 26'!B30) -> https://resolver.kb.nl/resolve?urn=ddd:011198687:mpeg21:p013 | C39: ='News Articles 26'!C30 -> Real Madrid has not seen Cruyff.... | D39: =IF(B39="N/A","N/A",'News Articles 26'!D30) -> 74fc232444af3ea1c1be0dc8c48e8107
A40: ='News Articles 26'!A65 -> 8564 | B40: =IF(_xlfn.XLOOKUP(A40,Test!$A$2:$A$801,Test!$A$2:$A$801,0),"N/A",'News Articles 26'!B65) -> https://resolver.kb.nl/resolve?urn=ddd:011182224:mpeg21:p003 | C40: ='News Articles 26'!C65 -> For The People's Friend. The Jews in Russia. | D40: =IF(B40="N/A","N/A",'News Articles 26'!D65) -> 5434077d0114e9fd78ee8475bb9b02ff
...

Sheet Survey
A1: article_id | B1: article_url | C1: article_title | D1: image_id
A2: 8511 | B2: https://resolver.kb.nl/resolve?urn=ABCDDD:010880247:mpeg21:p001 | C2: Landslide French elections De Gaulle's great triumph: absolute majority | D2: dd01a756e57d52f9a86b53fed235c7fb
A3: 8516 | B3: https://resolver.kb.nl/resolve?urn=ABCDDD:010882366:mpeg21:p001 | C3: British-Dutch cooperation MARINE DEPLOYED ON OIL ROUTE Frigate patrol to Indian Ocean | D3: bdf3112dfa9b3371b12c51649225dc44
A4: 8519 | B4: https://resolver.kb.nl/resolve?urn=ABCDDD:010880416:mpeg21:p003 | C4: MORE THAN MILLION SPECTATORS Departure of Apollo 16 went smoothly | D4: b8e61a11c988641a045c570eb33a88e3
A5: 8526 | B5: https://resolver.kb.nl/resolve?urn=ABCDDD:010880796:mpeg21:p001 | C5: Fifty thousand demonstrators in Lisbon | D5: 416e267d2780fffd044541afb21d42ae
A6: 8546 | B6: https://resolver.kb.nl/resolve?urn=ddd:011235935:mpeg21:p007 | C6: NO ATTACK ON BALKANS Brezhnev calms Tito's fears | D6: 4ee97bdf7dd3175c3507b7a6dce3a7bd
A7: 8598 | B7: https://resolver.kb.nl/resolve?urn=ABCDDD:010866779:mpeg21:p006 | C7: At least 60,000 Hutu's flee Rwandan capital Tutsi rebels surround Kigali | D7: f5c7d906aa8ef471c19232a73c2fe88e
A8: 8865 | B8: https://assets.msn.com/labs/mind/AADcUqA.html | C8: Release of whales from notorious Russia 'whale jail' complete | D8: 38123da22ae44e30ab899e425a320d00
A9: 9181 | B9: https://assets.msn.com/labs/mind/AAJX5z6.html | C9: Mercury transit is coming to a sky near you Monday. And it won't happen again until 2032. | D9: 5873e024b2114c63a7242336b8618011
A10: 9621 | B10: https://assets.msn.com/labs/mind/AAJTJOp.html | C10: Cincinnati Zoo pairs up cute rescue dog Remus and baby cheetah Kris for a 'BFF sleepover' | D10: 13e7bf82e6b7458ca72e15f0796befd1
A11: 10741 | B11: https://assets.msn.com/labs/mind/BBWE2bj.html | C11: Sydney Landmarks Shrouded in Haze From New South Wales Fires | D11: f1aa185e3b254b818cf856b7f595f77d
A12: 11115 | B12: https://assets.msn.com/labs/mind/BBWE7xl.html | C12: Meteor spotted streaking across the midwest sky | D12: 2183b9267b9c480a9d1327f17c38bd78
A13: 11292 | B13: https://assets.msn.com/labs/mind/BBWEA7Y.html | C13: NASA Spots Massive, Trippy Thermonuclear Blast | D13: 7b17f91c5d50430ebb095c1542d6d468
... A36: 23503 | B36: https://assets.msn.com/labs/mind/BBWybSc.html | C36: American forces on patrol amid contentious Syrian offensive | D36: 468e263e5ab5453f99c3c1b95b732766
